Upon reviewing the warning, I conclude that it is @@ unactionable @@.

The warning is reporting a catch block that catches the general Exception class, which can potentially mask other exceptions that may occur. However, in this specific case, the catch block is not entirely empty, and it does set the `valid` variable to `false` when an exception is caught.

The code is trying to validate a pooled connection, and if an exception occurs during the validation process, it sets the `valid` variable to `false`. This suggests that the code is intentionally catching the general Exception class to handle any unexpected errors that may occur during the validation process.

Given the context, it appears that the code is handling the exception in a way that makes sense for the specific use case. Therefore, this warning does not indicate a specific issue that needs to be addressed, and it can be considered unactionable.